Traceback (most recent call last):
  File "/Users/phil/a50037/envs/jbenv/lib/python3.7/site-packages/jupyter_cache/executors/basic.py", line 163, in execute
    executenb(nb_bundle.nb, cwd=tmpdirname, timeout=timeout)
  File "/Users/phil/a50037/envs/jbenv/lib/python3.7/site-packages/nbconvert/preprocessors/execute.py", line 737, in executenb
    return ep.preprocess(nb, resources, km=km)[0]
  File "/Users/phil/a50037/envs/jbenv/lib/python3.7/site-packages/nbconvert/preprocessors/execute.py", line 405, in preprocess
    nb, resources = super(ExecutePreprocessor, self).preprocess(nb, resources)
  File "/Users/phil/a50037/envs/jbenv/lib/python3.7/site-packages/nbconvert/preprocessors/base.py", line 69, in preprocess
    nb.cells[index], resources = self.preprocess_cell(cell, resources, index)
  File "/Users/phil/a50037/envs/jbenv/lib/python3.7/site-packages/nbconvert/preprocessors/execute.py", line 448, in preprocess_cell
    raise CellExecutionError.from_cell_and_msg(cell, out)
nbconvert.preprocessors.execute.CellExecutionError: An error occurred while executing the following cell:
------------------
>>> import serial
>>> print(serial.__version__)
------------------

[0;31m---------------------------------------------------------------------------[0m
[0;31mModuleNotFoundError[0m                       Traceback (most recent call last)
[0;32m<ipython-input-1-da3f7ec03343>[0m in [0;36m<module>[0;34m[0m
[0;32m----> 1[0;31m [0;32mimport[0m [0mserial[0m[0;34m[0m[0;34m[0m[0m
[0m[1;32m      2[0m [0mprint[0m[0;34m([0m[0mserial[0m[0;34m.[0m[0m__version__[0m[0;34m)[0m[0;34m[0m[0;34m[0m[0m

[0;31mModuleNotFoundError[0m: No module named 'serial'
ModuleNotFoundError: No module named 'serial'

